Workbook

Sheet Instructions
A1: MAP 340B Compliance + Analytics System
A3: What this workbook does | B3: Imports January 2025 MAP claims, applies scrubbing rules, assigns risk scores, and provides a dashboard.
A5: Required 2025 review fields | D5: India team benchmarks
B6: Prescription number | D6: Week 1 target / analyst | E6: 100 claims/day
B7: Fill date | D7: Steady-state target / analyst | E7: 150-200 claims/day
B8: Drug name | D8: Combined team target | E8: 300-400 claims/day
B9: NDC | D9: QA review sample | E9: 10% daily
B10: Prescribing provider | D10: Accuracy target | E10: >99%
B11: Provider NPI
B12: Site location
B13: Pharmacy location | D13: How to use
B14: Patient encounter site | D14: 1. Review Raw_Data imported from January '25.xlsx.
B15: 340B ID | D15: 2. Complete Store_Map for each store number.
B16: Covered entity | D16: 3. Complete Site_Entity_Map with valid site / 340B ID / covered entity details.
B17: Entity site address | D17: 4. Review Scrubbing_Engine for PASS/REVIEW flags and risk score.
D18: 5. Use Dashboard and Daily_Production for reporting.

Sheet Raw_Data
A1: Prescription number | B1: Fill date | C1: Drug name | D1: NDC | E1: Prescribing provider | F1: Provider NPI | G1: Provider address | H1: Store number | I1: Patient name | J1: Patient birthdate
A2: 6249548 | B2: 45659 | C2: TAMSULOSIN HCL 0.4 MG CAPSU | D2: 65862059801 | E2: GIBBS, JON | F2: 1700896156 | G2: 3651 WHEELER RD | H2: 0 | I2: BROWN***, ROBERT C | J2: 19975
A3: 6250699 | B3: 45659 | C3: MECLIZINE 25 MG TABLET | D3: 16571066101 | E3: GIBBS, JON | F3: 1700896156 | G3: 3651 WHEELER RD | H3: 0 | I3: FROST, JERRY A | J3: 22991
A4: 6250960 | B4: 45659 | C4: PROPRANOLOL ER 60 MG CAPSUL | D4: 228277811 | E4: BYNE, EDMUND | F4: 1033186648 | G4: 480 MARTIN LUTHER KING RD | H4: 0 | I4: KENNEDY, HOLLIE R | J4: 33415
A5: 6250242 | B5: 45659 | C5: METFORMIN HCL 1,000 MG TABL | D5: 65862001099 | E5: BYNE, EDMUND | F5: 1033186648 | G5: 480 MARTIN LUTHER KING RD | H5: 0 | I5: PARKS, KERRY | J5: 22394
A6: 6238783 | B6: 45659 | C6: METFORMIN HCL 500 MG TABLET | D6: 68382075805 | E6: BYNE, EDMUND | F6: 1033186648 | G6: 480 MARTIN LUTHER KING RD | H6: 0 | I6: BLOUNT, PENNY R | J6: 25643
A7: 6238778 | B7: 45659 | C7: TIZANIDINE HCL 4 MG TABLET | D7: 57664050389 | E7: BYNE, EDMUND | F7: 1033186648 | G7: 480 MARTIN LUTHER KING RD | H7: 0 | I7: BLOUNT, PENNY R | J7: 25643
A8: 6247451 | B8: 45659 | C8: INSULIN LISPRO 100 UNIT/MLP | D8: 2822259 | E8: GIBBS, JON | F8: 1700896156 | G8: 3651 WHEELER RD | H8: 0 | I8: BEARD***, QUIANTANNA N | J8: 30631
A9: 6246683 | B9: 45659 | C9: ATORVASTATIN 10 MG TABLET | D9: 67877051190 | E9: GIBBS, JON | F9: 1700896156 | G9: 3651 WHEELER RD | H9: 0 | I9: PALMER, GLORIER | J9: 21910
A10: 6249118 | B10: 45659 | C10: ATORVASTATIN 80 MG TABLET | D10: 378395305 | E10: MACHADO, MARIA | F10: 1619100302 | G10: 2467 GOLDEN CAMP RD | H10: 0 | I10: BEARD***, QUIANTANNA N | J10: 30631
A11: 6249137 | B11: 45659 | C11: OMEPRAZOLE DR 20 MG CAPSULE | D11: 68382041205 | E11: BYNE, EDMUND | F11: 1033186648 | G11: 480 MARTIN LUTHER KING RD | H11: 0 | I11: HARRIS***, THELMA P | J11: 20557
A12: 6249138 | B12: 45659 | C12: BACLOFEN 10 MG TABLET | D12: 52817032000 | E12: BYNE, EDMUND | F12: 1033186648 | G12: 480 MARTIN LUTHER KING RD | H12: 0 | I12: HARRIS***, THELMA P | J12: 20557
A13: 6249364 | B13: 45659 | C13: OZEMPIC 1 MG/DOSE (4 MG/3 M | D13: 169413013 | E13: MACHADO, MARIA | F13: 1619100302 | G13: 2467 GOLDEN CAMP RD | H13: 0 | I13: TUCKER***, TIKERA | J13: 30121
... A371: 6251313 | B371: 45660 | C371: ALBUTEROL HFA 90 MCG INHALE | D371: 781729685 | E371: DEANGELO, ALAN | F371: 1982741237 | G371: 3623 J DEWEY GRAY CIRCLE | H371: 0 | I371: MCCORD, STEPHEN C | J371: 29683
A372: 6251314 | B372: 45660 | C372: AZITHROMYCIN 250 MG TABLET | D372: 50111078751 | E372: AKHTAR, MIRIAM | F372: 1780024596 | H372: 0 | I372: HEATH, CHIQUITA T | J372: 27603
A373: 6246274 | B373: 45660 | C373: SERTRALINE HCL 50 MG TABLET | D373: 65862001205 | E373: BYNE, EDMUND | F373: 1033186648 | G373: 480 MARTIN LUTHER KING RD | H373: 0 | I373: HUNT, KIMBERLY D | J373: 22616
A374: 6246273 | B374: 45660 | C374: SERTRALINE HCL 100 MG TABLE | D374: 65862001305 | E374: BYNE, EDMUND | F374: 1033186648 | G374: 480 MARTIN LUTHER KING RD | H374: 0 | I374: HUNT, KIMBERLY D | J374: 22616
A375: 6249699 | B375: 45660 | C375: AMLODIPINE BESYLATE 5 MG TA | D375: 69097012715 | E375: BYNE, EDMUND | F375: 1033186648 | G375: 480 MARTIN LUTHER KING RD | H375: 0 | I375: FLEMING, ASHLEY | J375: 33579
A376: 6251315 | B376: 45660 | C376: ALBUTEROL HFA 90 MCG INHALE | D376: 93317431 | E376: AKHTAR, MIRIAM | F376: 1780024596 | H376: 0 | I376: HEATH, CHIQUITA T | J376: 27603
A377: 6251316 | B377: 45660 | C377: AMOX-CLAV 875-125 MG TABLET | D377: 42571016242 | E377: GIBBS, JON | F377: 1700896156 | G377: 3651 WHEELER RD | H377: 0 | I377: CLINTON, NIYTISHA | J377: 34619
A378: 6251317 | B378: 45660 | C378: METHYLPREDNISOLONE 4 MG DOS | D378: 59746000103 | E378: GIBBS, JON | F378: 1700896156 | G378: 3651 WHEELER RD | H378: 0 | I378: CLINTON, NIYTISHA | J378: 34619
A379: 6249943 | B379: 45663 | C379: GABAPENTIN 400 MG CAPSULE | D379: 69097081507 | E379: AKHTAR, MARIAM | F379: 1780024596 | G379: 2467 GOLDEN CAMP RD | H379: 0 | I379: SCHNOVEL, TANYA L | J379: 32951
A380: 6241642 | B380: 45663 | C380: NIFEDIPINE ER 90 MG TABLET | D380: 62175026237 | E380: YASIN, NURA | F380: 1265518567 | G380: 1111 GARREDD BLVD | H380: 0 | I380: MCCANTS***, BARBARA J | J380: 21968
A381: 6249376 | B381: 45663 | C381: LOSARTAN POTASSIUM 50 MG TA | D381: 65862020299 | E381: GIBBS, JON | F381: 1700896156 | G381: 3651 WHEELER RD | H381: 0 | I381: WALTON***, JOHN | J381: 17993
A382: 6249383 | B382: 45663 | C382: CARVEDILOL 12.5 MG TABLET | D382: 68382009405 | E382: GIBBS, JON | F382: 1700896156 | G382: 3651 WHEELER RD | H382: 0 | I382: WALTON***, JOHN | J382: 17993
A383: 6250016 | B383: 45663 | C383: *DICLOFENAC SOD DR 50 MG TA | D383: 61442010260 | E383: SUN, ZHOU | F383: 1164837415 | G383: 1120 15TH ST BIW 2144 | H383: 0 | I383: TERRELL, RUTHIE L | J383: 18769
A384: 6246587 | B384: 45663 | C384: OZEMPIC 0.25-0.5 MG/DOSE PE | D384: 169418113 | E384: BYNE, EDMUND | F384: 1033186648 | G384: 480 MARTIN LUTHER KING RD | H384: 0 | I384: MCFADDEN, JASMINE | J384: 33845
A385: 6250936 | B385: 45663 | C385: IBUPROFEN 800 MG TABLET | D385: 59651036205 | E385: GIBBS, JON | F385: 1700896156 | G385: 3651 WHEELER RD | H385: 0 | I385: JOHNSON**, CAMULA L | J385: 26737
A386: 6251076 | B386: 45663 | C386: BACLOFEN 10 MG TABLET | D386: 52817032000 | E386: BYNE, EDMUND | F386: 1033186648 | G386: 480 MARTIN LUTHER KING RD | H386: 0 | I386: PONDER***, TAHREA D | J386: 28914
A387: 6246442 | B387: 45663 | C387: TRINTELLIX 10 MG TABLET | D387: 64764073030 | E387: BYNE, EDMUND | F387: 1033186648 | G387: 480 MARTIN LUTHER KING RD | H387: 0 | I387: SAMUELS***, NAPOLEON I | J387: 23655
A388: 6250124 | B388: 45663 | C388: CETIRIZINE HCL 10 MG TABLET | D388: 904671746 | E388: BYNE, EDMUND | F388: 1033186648 | G388: 480 MARTIN LUTHER KING RD | H388: 0 | I388: PRIESTER***, DENISHA R | J388: 29674
... A3160: 6253070 | B3160: 45685 | C3160: *AMOXICILLIN 875 MG TABLET | D3160: 65862001501 | E3160: GROTZ, KENNETH | F3160: 1063521631 | G3160: 104 N. BELAIR RD | H3160: 0 | I3160: IVEY, HARMONY | J3160: 40154
A3161: 6253071 | B3161: 45685 | C3161: IBUPROFEN 800 MG TABLET | D3161: 59651036205 | E3161: AKHTAR, MIRIAM | F3161: 1780024596 | H3161: 0 | I3161: JONES***, DAVID | J3161: 22374
A3162: 6253072 | B3162: 45685 | C3162: LOSARTAN POTASSIUM 50 MG TA | D3162: 65862020299 | E3162: AKHTAR, MARIAM | F3162: 1780024596 | G3162: 2467 GOLDEN CAMP RD | H3162: 0 | I3162: JONES***, DAVID | J3162: 22374
A3163: 2003378 | B3163: 45685 | C3163: DEXTROAMP-AMPHET ER 20 MG C | D3163: 115148901 | E3163: Acevedo, Jose | F3163: 1356327027 | G3163: 1299 INTERSTATE PKWY | H3163: 0 | I3163: MASON, MAXIMILLION | J3163: 39721
A3164: 6253074 | B3164: 45685 | C3164: ATORVASTATIN 20 MG TABLET | D3164: 60505257908 | E3164: BYNE, EDMUND | F3164: 1033186648 | G3164: 480 MARTIN LUTHER KING RD | H3164: 0 | I3164: OWEN, LEILA | J3164: 20053
A3165: 6253076 | B3165: 45685 | C3165: VENTOLIN HFA 90 MCG INHALER | D3165: 173068220 | E3165: BYNE, EDMUND | F3165: 1033186648 | G3165: 480 MARTIN LUTHER KING RD | H3165: 0 | I3165: THOMPKINS, CATHY A | J3165: 21878
A3166: 6253078 | B3166: 45685 | C3166: FLUTICASONE-VILANTEROL 100- | D3166: 66993013597 | E3166: YASIN, NURA | F3166: 1265518567 | G3166: 1111 GARREDD BLVD | H3166: 0 | I3166: WILLIAMS, STEPHANIE S | J3166: 21661
A3167: 6253079 | B3167: 45685 | C3167: HYDROCHLOROTHIAZIDE 12.5 MG | D3167: 69315015510 | E3167: YASIN, NURA | F3167: 1265518567 | G3167: 1111 GARREDD BLVD | H3167: 0 | I3167: WILLIAMS, STEPHANIE S | J3167: 21661
A3168: 6253080 | B3168: 45685 | C3168: LOSARTAN POTASSIUM 50 MG TA | D3168: 65862020299 | E3168: YASIN, NURA | F3168: 1265518567 | G3168: 1111 GARREDD BLVD | H3168: 0 | I3168: WILLIAMS, STEPHANIE S | J3168: 21661
...

Sheet Store_Map
A1: Store number | B1: Scripts in Jan 2025 | C1: Pharmacy location | D1: Site location | E1: Patient encounter site | F1: 340B ID | G1: Covered entity | H1: Entity site address | I1: Store map status
A2: 0 | B2: 3763 | I2: =IF(COUNTA(C2:H2)=6,"Complete","Needs update") -> Needs update
A3: 1 | B3: 1045 | I3: =IF(COUNTA(C3:H3)=6,"Complete","Needs update") -> Needs update
A4: 2 | B4: 2230 | I4: =IF(COUNTA(C4:H4)=6,"Complete","Needs update") -> Needs update
A5: 3 | B5: 1018 | I5: =IF(COUNTA(C5:H5)=6,"Complete","Needs update") -> Needs update
A6: 4 | B6: 2 | I6: =IF(COUNTA(C6:H6)=6,"Complete","Needs update") -> Needs update

Sheet Site_Entity_Map
A1: Site location | B1: Valid patient encounter site | C1: 340B ID | D1: Covered entity | E1: Entity site address | F1: Active Y/N
F2: Y

Sheet Scrubbing_Engine
A1: Prescription number | B1: Fill date | C1: Drug name | D1: NDC | E1: Prescribing provider | F1: Provider NPI | G1: Store number | H1: Pharmacy location | I1: Site location | J1: Patient encounter site | K1: 340B ID | L1: Covered entity | M1: Entity site address | N1: Missing fields | O1: NPI check | P1: NDC check | Q1: Store map | R1: Entity map | S1: Overall status | T1: Risk score | U1: Risk tier | V1: Primary issue
A2: =Raw_Data!A2 -> 6249548 | B2: =Raw_Data!B2 -> 45659 | C2: =Raw_Data!C2 -> TAMSULOSIN HCL 0.4 MG CAPSU | D2: =Raw_Data!D2 -> 65862059801 | E2: =Raw_Data!E2 -> GIBBS, JON | F2: =Raw_Data!F2 -> 1700896156 | G2: =Raw_Data!H2 -> 0 | H2: =IFERROR(VLOOKUP(G2,Store_Map!$A$2:$I$100,3,FALSE),"") -> 0 | I2: =IFERROR(VLOOKUP(G2,Store_Map!$A$2:$I$100,4,FALSE),"") -> 0 | J2: =IFERROR(VLOOKUP(G2,Store_Map!$A$2:$I$100,5,FALSE),"") -> 0 | K2: =IFERROR(VLOOKUP(G2,Store_Map!$A$2:$I$100,6,FALSE),"") -> 0 | L2: =IFERROR(VLOOKUP(G2,Store_Map!$A$2:$I$100,7,FALSE),"") -> 0 | M2: =IFERROR(VLOOKUP(G2,Store_Map!$A$2:$I$100,8,FALSE),"") -> 0 | N2: =COUNTBLANK(A2:M2) -> 0 | O2: =IF(AND(F2<>"",LEN(F2)=10,ISNUMBER(--F2)),"PASS","REVIEW") -> PASS | P2: =IF(AND(D2<>"",OR(LEN(D2)=10,LEN(D2)=11),ISNUMBER(--D2)),"PASS","REVIEW") -> PASS | Q2: =IF(H2<>"","PASS","REVIEW") -> PASS | R2: =IF(AND(I2<>"",J2<>"",K2<>"",L2<>"",M2<>""),"PASS","REVIEW") -> PASS | S2: =IF(OR(N2>0,O2="REVIEW",P2="REVIEW",Q2="REVIEW",R2="REVIEW"),"REVIEW","PASS") -> PASS | T2: =MAX(0,100-(N2*5)-IF(O2="REVIEW",15,0)-IF(P2="REVIEW",10,0)-IF(Q2="REVIEW",10,0)-IF(R2="REVIEW",20,0)) -> 100 | U2: =IF(T2>=90,"Low",IF(T2>=70,"Medium","High")) -> Low | V2: =IF(N2>0,"Missing required fields",IF(O2="REVIEW","Invalid provider NPI",IF(P2="REVIEW","Invalid NDC",IF(Q2="REVIEW","Store mapping incomplete",IF(R2="REVIEW","Entity mapping incomplete","Clean"))))) -> Clean
A3: =Raw_Data!A3 -> 6250699 | B3: =Raw_Data!B3 -> 45659 | C3: =Raw_Data!C3 -> MECLIZINE 25 MG TABLET | D3: =Raw_Data!D3 -> 16571066101 | E3: =Raw_Data!E3 -> GIBBS, JON | F3: =Raw_Data!F3 -> 1700896156 | G3: =Raw_Data!H3 -> 0 | H3: =IFERROR(VLOOKUP(G3,Store_Map!$A$2:$I$100,3,FALSE),"") -> 0 | I3: =IFERROR(VLOOKUP(G3,Store_Map!$A$2:$I$100,4,FALSE),"") -> 0 | J3: =IFERROR(VLOOKUP(G3,Store_Map!$A$2:$I$100,5,FALSE),"") -> 0 | K3: =IFERROR(VLOOKUP(G3,Store_Map!$A$2:$I$100,6,FALSE),"") -> 0 | L3: =IFERROR(VLOOKUP(G3,Store_Map!$A$2:$I$100,7,FALSE),"") -> 0 | M3: =IFERROR(VLOOKUP(G3,Store_Map!$A$2:$I$100,8,FALSE),"") -> 0 | N3: =COUNTBLANK(A3:M3) -> 0 | O3: =IF(AND(F3<>"",LEN(F3)=10,ISNUMBER(--F3)),"PASS","REVIEW") -> PASS | P3: =IF(AND(D3<>"",OR(LEN(D3)=10,LEN(D3)=11),ISNUMBER(--D3)),"PASS","REVIEW") -> PASS | Q3: =IF(H3<>"","PASS","REVIEW") -> PASS | R3: =IF(AND(I3<>"",J3<>"",K3<>"",L3<>"",M3<>""),"PASS","REVIEW") -> PASS | S3: =IF(OR(N3>0,O3="REVIEW",P3="REVIEW",Q3="REVIEW",R3="REVIEW"),"REVIEW","PASS") -> PASS | T3: =MAX(0,100-(N3*5)-IF(O3="REVIEW",15,0)-IF(P3="REVIEW",10,0)-IF(Q3="REVIEW",10,0)-IF(R3="REVIEW",20,0)) -> 100 | U3: =IF(T3>=90,"Low",IF(T3>=70,"Medium","High")) -> Low | V3: =IF(N3>0,"Missing required fields",IF(O3="REVIEW","Invalid provider NPI",IF(P3="REVIEW","Invalid NDC",IF(Q3="REVIEW","Store mapping incomplete",IF(R3="REVIEW","Entity mapping incomplete","Clean"))))) -> Clean
A4: =Raw_Data!A4 -> 6250960 | B4: =Raw_Data!B4 -> 45659 | C4: =Raw_Data!C4 -> PROPRANOLOL ER 60 MG CAPSUL | D4: =Raw_Data!D4 -> 228277811 | E4: =Raw_Data!E4 -> BYNE, EDMUND | F4: =Raw_Data!F4 -> 1033186648 | G4: =Raw_Data!H4 -> 0 | H4: =IFERROR(VLOOKUP(G4,Store_Map!$A$2:$I$100,3,FALSE),"") -> 0 | I4: =IFERROR(VLOOKUP(G4,Store_Map!$A$2:$I$100,4,FALSE),"") -> 0 | J4: =IFERROR(VLOOKUP(G4,Store_Map!$A$2:$I$100,5,FALSE),"") -> 0 | K4: =IFERROR(VLOOKUP(G4,Store_Map!$A$2:$I$100,6,FALSE),"") -> 0 | L4: =IFERROR(VLOOKUP(G4,Store_Map!$A$2:$I$100,7,FALSE),"") -> 0 | M4: =IFERROR(VLOOKUP(G4,Store_Map!$A$2:$I$100,8,FALSE),"") -> 0 | N4: =COUNTBLANK(A4:M4) -> 0 | O4: =IF(AND(F4<>"",LEN(F4)=10,ISNUMBER(--F4)),"PASS","REVIEW") -> PASS | P4: =IF(AND(D4<>"",OR(LEN(D4)=10,LEN(D4)=11),ISNUMBER(--D4)),"PASS","REVIEW") -> REVIEW | Q4: =IF(H4<>"","PASS","REVIEW") -> PASS | R4: =IF(AND(I4<>"",J4<>"",K4<>"",L4<>"",M4<>""),"PASS","REVIEW") -> PASS | S4: =IF(OR(N4>0,O4="REVIEW",P4="REVIEW",Q4="REVIEW",R4="REVIEW"),"REVIEW","PASS") -> REVIEW | T4: =MAX(0,100-(N4*5)-IF(O4="REVIEW",15,0)-IF(P4="REVIEW",10,0)-IF(Q4="REVIEW",10,0)-IF(R4="REVIEW",20,0)) -> 90 | U4: =IF(T4>=90,"Low",IF(T4>=70,"Medium","High")) -> Low | V4: =IF(N4>0,"Missing required fields",IF(O4="REVIEW","Invalid provider NPI",IF(P4="REVIEW","Invalid NDC",IF(Q4="REVIEW","Store mapping incomplete",IF(R4="REVIEW","Entity mapping incomplete","Clean"))))) -> Invalid NDC
A5: =Raw_Data!A5 -> 6250242 | B5: =Raw_Data!B5 -> 45659 | C5: =Raw_Data!C5 -> METFORMIN HCL 1,000 MG TABL | D5: =Raw_Data!D5 -> 65862001099 | E5: =Raw_Data!E5 -> BYNE, EDMUND | F5: =Raw_Data!F5 -> 1033186648 | G5: =Raw_Data!H5 -> 0 | H5: =IFERROR(VLOOKUP(G5,Store_Map!$A$2:$I$100,3,FALSE),"") -> 0 | I5: =IFERROR(VLOOKUP(G5,Store_Map!$A$2:$I$100,4,FALSE),"") -> 0 | J5: =IFERROR(VLOOKUP(G5,Store_Map!$A$2:$I$100,5,FALSE),"") -> 0 | K5: =IFERROR(VLOOKUP(G5,Store_Map!$A$2:$I$100,6,FALSE),"") -> 0 | L5: =IFERROR(VLOOKUP(G5,Store_Map!$A$2:$I$100,7,FALSE),"") -> 0 | M5: =IFERROR(VLOOKUP(G5,Store_Map!$A$2:$I$100,8,FALSE),"") -> 0 | N5: =COUNTBLANK(A5:M5) -> 0 | O5: =IF(AND(F5<>"",LEN(F5)=10,ISNUMBER(--F5)),"PASS","REVIEW") -> PASS | P5: =IF(AND(D5<>"",OR(LEN(D5)=10,LEN(D5)=11),ISNUMBER(--D5)),"PASS","REVIEW") -> PASS | Q5: =IF(H5<>"","PASS","REVIEW") -> PASS | R5: =IF(AND(I5<>"",J5<>"",K5<>"",L5<>"",M5<>""),"PASS","REVIEW") -> PASS | S5: =IF(OR(N5>0,O5="REVIEW",P5="REVIEW",Q5="REVIEW",R5="REVIEW"),"REVIEW","PASS") -> PASS | T5: =MAX(0,100-(N5*5)-IF(O5="REVIEW",15,0)-IF(P5="REVIEW",10,0)-IF(Q5="REVIEW",10,0)-IF(R5="REVIEW",20,0)) -> 100 | U5: =IF(T5>=90,"Low",IF(T5>=70,"Medium","High")) -> Low | V5: =IF(N5>0,"Missing required fields",IF(O5="REVIEW","Invalid provider NPI",IF(P5="REVIEW","Invalid NDC",IF(Q5="REVIEW","Store mapping incomplete",IF(R5="REVIEW","Entity mapping incomplete","Clean"))))) -> Clean
A6: =Raw_Data!A6 -> 6238783 | B6: =Raw_Data!B6 -> 45659 | C6: =Raw_Data!C6 -> METFORMIN HCL 500 MG TABLET | D6: =Raw_Data!D6 -> 68382075805 | E6: =Raw_Data!E6 -> BYNE, EDMUND | F6: =Raw_Data!F6 -> 1033186648 | G6: =Raw_Data!H6 -> 0 | H6: =IFERROR(VLOOKUP(G6,Store_Map!$A$2:$I$100,3,FALSE),"") -> 0 | I6: =IFERROR(VLOOKUP(G6,Store_Map!$A$2:$I$100,4,FALSE),"") -> 0 | J6: =IFERROR(VLOOKUP(G6,Store_Map!$A$2:$I$100,5,FALSE),"") -> 0 | K6: =IFERROR(VLOOKUP(G6,Store_Map!$A$2:$I$100,6,FALSE),"") -> 0 | L6: =IFERROR(VLOOKUP(G6,Store_Map!$A$2:$I$100,7,FALSE),"") -> 0 | M6: =IFERROR(VLOOKUP(G6,Store_Map!$A$2:$I$100,8,FALSE),"") -> 0 | N6: =COUNTBLANK(A6:M6) -> 0 | O6: =IF(AND(F6<>"",LEN(F6)=10,ISNUMBER(--F6)),"PASS","REVIEW") -> PASS | P6: =IF(AND(D6<>"",OR(LEN(D6)=10,LEN(D6)=11),ISNUMBER(--D6)),"PASS","REVIEW") -> PASS | Q6: =IF(H6<>"","PASS","REVIEW") -> PASS | R6: =IF(AND(I6<>"",J6<>"",K6<>"",L6<>"",M6<>""),"PASS","REVIEW") -> PASS | S6: =IF(OR(N6>0,O6="REVIEW",P6="REVIEW",Q6="REVIEW",R6="REVIEW"),"REVIEW","PASS") -> PASS | T6: =MAX(0,100-(N6*5)-IF(O6="REVIEW",15,0)-IF(P6="REVIEW",10,0)-IF(Q6="REVIEW",10,0)-IF(R6="REVIEW",20,0)) -> 100 | U6: =IF(T6>=90,"Low",IF(T6>=70,"Medium","High")) -> Low | V6: =IF(N6>0,"Missing required fields",IF(O6="REVIEW","Invalid provider NPI",IF(P6="REVIEW","Invalid NDC",IF(Q6="REVIEW","Store mapping incomplete",IF(R6="REVIEW","Entity mapping incomplete","Clean"))))) -> Clean
A7: =Raw_Data!A7 -> 6238778 | B7: =Raw_Data!B7 -> 45659 | C7: =Raw_Data!C7 -> TIZANIDINE HCL 4 MG TABLET | D7: =Raw_Data!D7 -> 57664050389 | E7: =Raw_Data!E7 -> BYNE, EDMUND | F7: =Raw_Data!F7 -> 1033186648 | G7: =Raw_Data!H7 -> 0 | H7: =IFERROR(VLOOKUP(G7,Store_Map!$A$2:$I$100,3,FALSE),"") -> 0 | I7: =IFERROR(VLOOKUP(G7,Store_Map!$A$2:$I$100,4,FALSE),"") -> 0 | J7: =IFERROR(VLOOKUP(G7,Store_Map!$A$2:$I$100,5,FALSE),"") -> 0 | K7: =IFERROR(VLOOKUP(G7,Store_Map!$A$2:$I$100,6,FALSE),"") -> 0 | L7: =IFERROR(VLOOKUP(G7,Store_Map!$A$2:$I$100,7,FALSE),"") -> 0 | M7: =IFERROR(VLOOKUP(G7,Store_Map!$A$2:$I$100,8,FALSE),"") -> 0 | N7: =COUNTBLANK(A7:M7) -> 0 | O7: =IF(AND(F7<>"",LEN(F7)=10,ISNUMBER(--F7)),"PASS","REVIEW") -> PASS | P7: =IF(AND(D7<>"",OR(LEN(D7)=10,LEN(D7)=11),ISNUMBER(--D7)),"PASS","REVIEW") -> PASS | Q7: =IF(H7<>"","PASS","REVIEW") -> PASS | R7: =IF(AND(I7<>"",J7<>"",K7<>"",L7<>"",M7<>""),"PASS","REVIEW") -> PASS | S7: =IF(OR(N7>0,O7="REVIEW",P7="REVIEW",Q7="REVIEW",R7="REVIEW"),"REVIEW","PASS") -> PASS | T7: =MAX(0,100-(N7*5)-IF(O7="REVIEW",15,0)-IF(P7="REVIEW",10,0)-IF(Q7="REVIEW",10,0)-IF(R7="REVIEW",20,0)) -> 100 | U7: =IF(T7>=90,"Low",IF(T7>=70,"Medium","High")) -> Low | V7: =IF(N7>0,"Missing required fields",IF(O7="REVIEW","Invalid provider NPI",IF(P7="REVIEW","Invalid NDC",IF(Q7="REVIEW","Store mapping incomplete",IF(R7="REVIEW","Entity mapping incomplete","Clean"))))) -> Clean
A8: =Raw_Data!A8 -> 6247451 | B8: =Raw_Data!B8 -> 45659 | C8: =Raw_Data!C8 -> INSULIN LISPRO 100 UNIT/MLP | D8: =Raw_Data!D8 -> 2822259 | E8: =Raw_Data!E8 -> GIBBS, JON | F8: =Raw_Data!F8 -> 1700896156 | G8: =Raw_Data!H8 -> 0 | H8: =IFERROR(VLOOKUP(G8,Store_Map!$A$2:$I$100,3,FALSE),"") -> 0 | I8: =IFERROR(VLOOKUP(G8,Store_Map!$A$2:$I$100,4,FALSE),"") -> 0 | J8: =IFERROR(VLOOKUP(G8,Store_Map!$A$2:$I$100,5,FALSE),"") -> 0 | K8: =IFERROR(VLOOKUP(G8,Store_Map!$A$2:$I$100,6,FALSE),"") -> 0 | L8: =IFERROR(VLOOKUP(G8,Store_Map!$A$2:$I$100,7,FALSE),"") -> 0 | M8: =IFERROR(VLOOKUP(G8,Store_Map!$A$2:$I$100,8,FALSE),"") -> 0 | N8: =COUNTBLANK(A8:M8) -> 0 | O8: =IF(AND(F8<>"",LEN(F8)=10,ISNUMBER(--F8)),"PASS","REVIEW") -> PASS | P8: =IF(AND(D8<>"",OR(LEN(D8)=10,LEN(D8)=11),ISNUMBER(--D8)),"PASS","REVIEW") -> REVIEW | Q8: =IF(H8<>"","PASS","REVIEW") -> PASS | R8: =IF(AND(I8<>"",J8<>"",K8<>"",L8<>"",M8<>""),"PASS","REVIEW") -> PASS | S8: =IF(OR(N8>0,O8="REVIEW",P8="REVIEW",Q8="REVIEW",R8="REVIEW"),"REVIEW","PASS") -> REVIEW | T8: =MAX(0,100-(N8*5)-IF(O8="REVIEW",15,0)-IF(P8="REVIEW",10,0)-IF(Q8="REVIEW",10,0)-IF(R8="REVIEW",20,0)) -> 90 | U8: =IF(T8>=90,"Low",IF(T8>=70,"Medium","High")) -> Low | V8: =IF(N8>0,"Missing required fields",IF(O8="REVIEW","Invalid provider NPI",IF(P8="REVIEW","Invalid NDC",IF(Q8="REVIEW","Store mapping incomplete",IF(R8="REVIEW","Entity mapping incomplete","Clean"))))) -> Invalid NDC
A9: =Raw_Data!A9 -> 6246683 | B9: =Raw_Data!B9 -> 45659 | C9: =Raw_Data!C9 -> ATORVASTATIN 10 MG TABLET | D9: =Raw_Data!D9 -> 67877051190 | E9: =Raw_Data!E9 -> GIBBS, JON | F9: =Raw_Data!F9 -> 1700896156 | G9: =Raw_Data!H9 -> 0 | H9: =IFERROR(VLOOKUP(G9,Store_Map!$A$2:$I$100,3,FALSE),"") -> 0 | I9: =IFERROR(VLOOKUP(G9,Store_Map!$A$2:$I$100,4,FALSE),"") -> 0 | J9: =IFERROR(VLOOKUP(G9,Store_Map!$A$2:$I$100,5,FALSE),"") -> 0 | K9: =IFERROR(VLOOKUP(G9,Store_Map!$A$2:$I$100,6,FALSE),"") -> 0 | L9: =IFERROR(VLOOKUP(G9,Store_Map!$A$2:$I$100,7,FALSE),"") -> 0 | M9: =IFERROR(VLOOKUP(G9,Store_Map!$A$2:$I$100,8,FALSE),"") -> 0 | N9: =COUNTBLANK(A9:M9) -> 0 | O9: =IF(AND(F9<>"",LEN(F9)=10,ISNUMBER(--F9)),"PASS","REVIEW") -> PASS | P9: =IF(AND(D9<>"",OR(LEN(D9)=10,LEN(D9)=11),ISNUMBER(--D9)),"PASS","REVIEW") -> PASS | Q9: =IF(H9<>"","PASS","REVIEW") -> PASS | R9: =IF(AND(I9<>"",J9<>"",K9<>"",L9<>"",M9<>""),"PASS","REVIEW") -> PASS | S9: =IF(OR(N9>0,O9="REVIEW",P9="REVIEW",Q9="REVIEW",R9="REVIEW"),"REVIEW","PASS") -> PASS | T9: =MAX(0,100-(N9*5)-IF(O9="REVIEW",15,0)-IF(P9="REVIEW",10,0)-IF(Q9="REVIEW",10,0)-IF(R9="REVIEW",20,0)) -> 100 | U9: =IF(T9>=90,"Low",IF(T9>=70,"Medium","High")) -> Low | V9: =IF(N9>0,"Missing required fields",IF(O9="REVIEW","Invalid provider NPI",IF(P9="REVIEW","Invalid NDC",IF(Q9="REVIEW","Store mapping incomplete",IF(R9="REVIEW","Entity mapping incomplete","Clean"))))) -> Clean
A10: =Raw_Data!A10 -> 6249118 | B10: =Raw_Data!B10 -> 45659 | C10: =Raw_Data!C10 -> ATORVASTATIN 80 MG TABLET | D10: =Raw_Data!D10 -> 378395305 | E10: =Raw_Data!E10 -> MACHADO, MARIA | F10: =Raw_Data!F10 -> 1619100302 | G10: =Raw_Data!H10 -> 0 | H10: =IFERROR(VLOOKUP(G10,Store_Map!$A$2:$I$100,3,FALSE),"") -> 0 | I10: =IFERROR(VLOOKUP(G10,Store_Map!$A$2:$I$100,4,FALSE),"") -> 0 | J10: =IFERROR(VLOOKUP(G10,Store_Map!$A$2:$I$100,5,FALSE),"") -> 0 | K10: =IFERROR(VLOOKUP(G10,Store_Map!$A$2:$I$100,6,FALSE),"") -> 0 | L10: =IFERROR(VLOOKUP(G10,Store_Map!$A$2:$I$100,7,FALSE),"") -> 0 | M10: =IFERROR(VLOOKUP(G10,Store_Map!$A$2:$I$100,8,FALSE),"") -> 0 | N10: =COUNTBLANK(A10:M10) -> 0 | O10: =IF(AND(F10<>"",LEN(F10)=10,ISNUMBER(--F10)),"PASS","REVIEW") -> PASS | P10: =IF(AND(D10<>"",OR(LEN(D10)=10,LEN(D10)=11),ISNUMBER(--D10)),"PASS","REVIEW") -> REVIEW | Q10: =IF(H10<>"","PASS","REVIEW") -> PASS | R10: =IF(AND(I10<>"",J10<>"",K10<>"",L10<>"",M10<>""),"PASS","REVIEW") -> PASS | S10: =IF(OR(N10>0,O10="REVIEW",P10="REVIEW",Q10="REVIEW",R10="REVIEW"),"REVIEW","PASS") -> REVIEW | T10: =MAX(0,100-(N10*5)-IF(O10="REVIEW",15,0)-IF(P10="REVIEW",10,0)-IF(Q10="REVIEW",10,0)-IF(R10="REVIEW",20,0)) -> 90 | U10: =IF(T10>=90,"Low",IF(T10>=70,"Medium","High")) -> Low | V10: =IF(N10>0,"Missing required fields",IF(O10="REVIEW","Invalid provider NPI",IF(P10="REVIEW","Invalid NDC",IF(Q10="REVIEW","Store mapping incomplete",IF(R10="REVIEW","Entity mapping incomplete","Clean"))))) -> Invalid NDC
A11: =Raw_Data!A11 -> 6249137 | B11: =Raw_Data!B11 -> 45659 | C11: =Raw_Data!C11 -> OMEPRAZOLE DR 20 MG CAPSULE | D11: =Raw_Data!D11 -> 68382041205 | E11: =Raw_Data!E11 -> BYNE, EDMUND | F11: =Raw_Data!F11 -> 1033186648 | G11: =Raw_Data!H11 -> 0 | H11: =IFERROR(VLOOKUP(G11,Store_Map!$A$2:$I$100,3,FALSE),"") -> 0 | I11: =IFERROR(VLOOKUP(G11,Store_Map!$A$2:$I$100,4,FALSE),"") -> 0 | J11: =IFERROR(VLOOKUP(G11,Store_Map!$A$2:$I$100,5,FALSE),"") -> 0 | K11: =IFERROR(VLOOKUP(G11,Store_Map!$A$2:$I$100,6,FALSE),"") -> 0 | L11: =IFERROR(VLOOKUP(G11,Store_Map!$A$2:$I$100,7,FALSE),"") -> 0 | M11: =IFERROR(VLOOKUP(G11,Store_Map!$A$2:$I$100,8,FALSE),"") -> 0 | N11: =COUNTBLANK(A11:M11) -> 0 | O11: =IF(AND(F11<>"",LEN(F11)=10,ISNUMBER(--F11)),"PASS","REVIEW") -> PASS | P11: =IF(AND(D11<>"",OR(LEN(D11)=10,LEN(D11)=11),ISNUMBER(--D11)),"PASS","REVIEW") -> PASS | Q11: =IF(H11<>"","PASS","REVIEW") -> PASS | R11: =IF(AND(I11<>"",J11<>"",K11<>"",L11<>"",M11<>""),"PASS","REVIEW") -> PASS | S11: =IF(OR(N11>0,O11="REVIEW",P11="REVIEW",Q11="REVIEW",R11="REVIEW"),"REVIEW","PASS") -> PASS | T11: =MAX(0,100-(N11*5)-IF(O11="REVIEW",15,0)-IF(P11="REVIEW",10,0)-IF(Q11="REVIEW",10,0)-IF(R11="REVIEW",20,0)) -> 100 | U11: =IF(T11>=90,"Low",IF(T11>=70,"Medium","High")) -> Low | V11: =IF(N11>0,"Missing required fields",IF(O11="REVIEW","Invalid provider NPI",IF(P11="REVIEW","Invalid NDC",IF(Q11="REVIEW","Store mapping incomplete",IF(R11="REVIEW","Entity mapping incomplete","Clean"))))) -> Clean
A12: =Raw_Data!A12 -> 6249138 | B12: =Raw_Data!B12 -> 45659 | C12: =Raw_Data!C12 -> BACLOFEN 10 MG TABLET | D12: =Raw_Data!D12 -> 52817032000 | E12: =Raw_Data!E12 -> BYNE, EDMUND | F12: =Raw_Data!F12 -> 1033186648 | G12: =Raw_Data!H12 -> 0 | H12: =IFERROR(VLOOKUP(G12,Store_Map!$A$2:$I$100,3,FALSE),"") -> 0 | I12: =IFERROR(VLOOKUP(G12,Store_Map!$A$2:$I$100,4,FALSE),"") -> 0 | J12: =IFERROR(VLOOKUP(G12,Store_Map!$A$2:$I$100,5,FALSE),"") -> 0 | K12: =IFERROR(VLOOKUP(G12,Store_Map!$A$2:$I$100,6,FALSE),"") -> 0 | L12: =IFERROR(VLOOKUP(G12,Store_Map!$A$2:$I$100,7,FALSE),"") -> 0 | M12: =IFERROR(VLOOKUP(G12,Store_Map!$A$2:$I$100,8,FALSE),"") -> 0 | N12: =COUNTBLANK(A12:M12) -> 0 | O12: =IF(AND(F12<>"",LEN(F12)=10,ISNUMBER(--F12)),"PASS","REVIEW") -> PASS | P12: =IF(AND(D12<>"",OR(LEN(D12)=10,LEN(D12)=11),ISNUMBER(--D12)),"PASS","REVIEW") -> PASS | Q12: =IF(H12<>"","PASS","REVIEW") -> PASS | R12: =IF(AND(I12<>"",J12<>"",K12<>"",L12<>"",M12<>""),"PASS","REVIEW") -> PASS | S12: =IF(OR(N12>0,O12="REVIEW",P12="REVIEW",Q12="REVIEW",R12="REVIEW"),"REVIEW","PASS") -> PASS | T12: =MAX(0,100-(N12*5)-IF(O12="REVIEW",15,0)-IF(P12="REVIEW",10,0)-IF(Q12="REVIEW",10,0)-IF(R12="REVIEW",20,0)) -> 100 | U12: =IF(T12>=90,"Low",IF(T12>=70,"Medium","High")) -> Low | V12: =IF(N12>0,"Missing required fields",IF(O12="REVIEW","Invalid provider NPI",IF(P12="REVIEW","Invalid NDC",IF(Q12="REVIEW","Store mapping incomplete",IF(R12="REVIEW","Entity mapping incomplete","Clean"))))) -> Clean
A13: =Raw_Data!A13 -> 6249364 | B13: =Raw_Data!B13 -> 45659 | C13: =Raw_Data!C13 -> OZEMPIC 1 MG/DOSE (4 MG/3 M | D13: =Raw_Data!D13 -> 169413013 | E13: =Raw_Data!E13 -> MACHADO, MARIA | F13: =Raw_Data!F13 -> 1619100302 | G13: =Raw_Data!H13 -> 0 | H13: =IFERROR(VLOOKUP(G13,Store_Map!$A$2:$I$100,3,FALSE),"") -> 0 | I13: =IFERROR(VLOOKUP(G13,Store_Map!$A$2:$I$100,4,FALSE),"") -> 0 | J13: =IFERROR(VLOOKUP(G13,Store_Map!$A$2:$I$100,5,FALSE),"") -> 0 | K13: =IFERROR(VLOOKUP(G13,Store_Map!$A$2:$I$100,6,FALSE),"") -> 0 | L13: =IFERROR(VLOOKUP(G13,Store_Map!$A$2:$I$100,7,FALSE),"") -> 0 | M13: =IFERROR(VLOOKUP(G13,Store_Map!$A$2:$I$100,8,FALSE),"") -> 0 | N13: =COUNTBLANK(A13:M13) -> 0 | O13: =IF(AND(F13<>"",LEN(F13)=10,ISNUMBER(--F13)),"PASS","REVIEW") -> PASS | P13: =IF(AND(D13<>"",OR(LEN(D13)=10,LEN(D13)=11),ISNUMBER(--D13)),"PASS","REVIEW") -> REVIEW | Q13: =IF(H13<>"","PASS","REVIEW") -> PASS | R13: =IF(AND(I13<>"",J13<>"",K13<>"",L13<>"",M13<>""),"PASS","REVIEW") -> PASS | S13: =IF(OR(N13>0,O13="REVIEW",P13="REVIEW",Q13="REVIEW",R13="REVIEW"),"REVIEW","PASS") -> REVIEW | T13: =MAX(0,100-(N13*5)-IF(O13="REVIEW",15,0)-IF(P13="REVIEW",10,0)-IF(Q13="REVIEW",10,0)-IF(R13="REVIEW",20,0)) -> 90 | U13: =IF(T13>=90,"Low",IF(T13>=70,"Medium","High")) -> Low | V13: =IF(N13>0,"Missing required fields",IF(O13="REVIEW","Invalid provider NPI",IF(P13="REVIEW","Invalid NDC",IF(Q13="REVIEW","Store mapping incomplete",IF(R13="REVIEW","Entity mapping incomplete","Clean"))))) -> Invalid NDC
... A8059: =Raw_Data!A8059 -> 46001011 | B8059: =Raw_Data!B8059 -> 45674 | C8059: =Raw_Data!C8059 -> AZITHROMYCIN 250 MG TABLET | D8059: =Raw_Data!D8059 -> 65862064169 | E8059: =Raw_Data!E8059 -> WILEY, DARYL | F8059: =Raw_Data!F8059 -> 1508859448 | G8059: =Raw_Data!H8059 -> 4 | H8059: =IFERROR(VLOOKUP(G8059,Store_Map!$A$2:$I$100,3,FALSE),"") -> 0 | I8059: =IFERROR(VLOOKUP(G8059,Store_Map!$A$2:$I$100,4,FALSE),"") -> 0 | J8059: =IFERROR(VLOOKUP(G8059,Store_Map!$A$2:$I$100,5,FALSE),"") -> 0 | K8059: =IFERROR(VLOOKUP(G8059,Store_Map!$A$2:$I$100,6,FALSE),"") -> 0 | L8059: =IFERROR(VLOOKUP(G8059,Store_Map!$A$2:$I$100,7,FALSE),"") -> 0 | M8059: =IFERROR(VLOOKUP(G8059,Store_Map!$A$2:$I$100,8,FALSE),"") -> 0 | N8059: =COUNTBLANK(A8059:M8059) -> 0 | O8059: =IF(AND(F8059<>"",LEN(F8059)=10,ISNUMBER(--F8059)),"PASS","REVIEW") -> PASS | P8059: =IF(AND(D8059<>"",OR(LEN(D8059)=10,LEN(D8059)=11),ISNUMBER(--D8059)),"PASS","REVIEW") -> PASS | Q8059: =IF(H8059<>"","PASS","REVIEW") -> PASS | R8059: =IF(AND(I8059<>"",J8059<>"",K8059<>"",L8059<>"",M8059<>""),"PASS","REVIEW") -> PASS | S8059: =IF(OR(N8059>0,O8059="REVIEW",P8059="REVIEW",Q8059="REVIEW",R8059="REVIEW"),"REVIEW","PASS") -> PASS | T8059: =MAX(0,100-(N8059*5)-IF(O8059="REVIEW",15,0)-IF(P8059="REVIEW",10,0)-IF(Q8059="REVIEW",10,0)-IF(R8059="REVIEW",20,0)) -> 100 | U8059: =IF(T8059>=90,"Low",IF(T8059>=70,"Medium","High")) -> Low | V8059: =IF(N8059>0,"Missing required fields",IF(O8059="REVIEW","Invalid provider NPI",IF(P8059="REVIEW","Invalid NDC",IF(Q8059="REVIEW","Store mapping incomplete",IF(R8059="REVIEW","Entity mapping incomplete","Clean"))))) -> Clean

Sheet Dashboard
A1: MAP 340B Scrubbing Engine Dashboard - January 2025
A2: Total claims imported | B2: =COUNTA(Raw_Data!A:A)-1 -> 8058 | D2: Critical issue counts | H2: Risk scoring logic
A3: PASS claims | B3: =COUNTIF(Scrubbing_Engine!S:S,"PASS") -> 6237 | D3: Missing required fields | E3: =COUNTIF(Scrubbing_Engine!V:V,"Missing required fields") -> 0 | H3: Start at 100 points
A4: REVIEW claims | B4: =COUNTIF(Scrubbing_Engine!S:S,"REVIEW") -> 1821 | D4: Invalid provider NPI | E4: =COUNTIF(Scrubbing_Engine!V:V,"Invalid provider NPI") -> 0 | H4: -5 per missing required field
A5: Pass rate | B5: =IF(B2=0,0,B3/B2) -> 0.7740134 | D5: Invalid NDC | E5: =COUNTIF(Scrubbing_Engine!V:V,"Invalid NDC") -> 1821 | H5: -15 invalid / missing provider NPI
A6: High risk claims | B6: =COUNTIF(Scrubbing_Engine!U:U,"High") -> 0 | D6: Store mapping incomplete | E6: =COUNTIF(Scrubbing_Engine!V:V,"Store mapping incomplete") -> 0 | H6: -10 invalid / missing NDC
A7: Medium risk claims | B7: =COUNTIF(Scrubbing_Engine!U:U,"Medium") -> 0 | D7: Entity mapping incomplete | E7: =COUNTIF(Scrubbing_Engine!V:V,"Entity mapping incomplete") -> 0 | H7: -10 missing store / pharmacy map
A8: Low risk claims | B8: =COUNTIF(Scrubbing_Engine!U:U,"Low") -> 8058 | H8: -20 missing site / entity / 340B details
A9: Average risk score | B9: =IF(B2=0,0,AVERAGE(Scrubbing_Engine!T2:T8059)) -> 97.740134 | H9: Low risk = 90-100
D10: Store / pharmacy location status | H10: Medium risk = 70-89
D11: Store number | E11: Scripts | F11: Map status | H11: High risk = <70
D12: 0 | E12: 3763 | F12: =IFERROR(VLOOKUP(D12,Store_Map!$A$2:$I$100,9,FALSE),"Needs update") -> Needs update
D13: 1 | E13: 1045 | F13: =IFERROR(VLOOKUP(D13,Store_Map!$A$2:$I$100,9,FALSE),"Needs update") -> Needs update
D14: 2 | E14: 2230 | F14: =IFERROR(VLOOKUP(D14,Store_Map!$A$2:$I$100,9,FALSE),"Needs update") -> Needs update
D15: 3 | E15: 1018 | F15: =IFERROR(VLOOKUP(D15,Store_Map!$A$2:$I$100,9,FALSE),"Needs update") -> Needs update
D16: 4 | E16: 2 | F16: =IFERROR(VLOOKUP(D16,Store_Map!$A$2:$I$100,9,FALSE),"Needs update") -> Needs update

Sheet Daily_Production
A1: Date | B1: Analyst | C1: Assigned claims | D1: Completed claims | E1: QA sample reviewed | F1: QA errors | G1: QA accuracy % | H1: Notes
A2: 2025-03-18 | B2: Analyst 1 | C2: 100 | G2: =IF(E2=0,"",1-(F2/E2))
A3: 2025-03-18 | B3: Analyst 2 | C3: 100 | G3: =IF(E3=0,"",1-(F3/E3))
A4: 2025-03-19 | B4: Analyst 1 | C4: 100 | G4: =IF(E4=0,"",1-(F4/E4))
A5: 2025-03-19 | B5: Analyst 2 | C5: 100 | G5: =IF(E5=0,"",1-(F5/E5))
A6: 2025-03-20 | B6: Analyst 1 | C6: 100 | G6: =IF(E6=0,"",1-(F6/E6))
A7: 2025-03-20 | B7: Analyst 2 | C7: 100 | G7: =IF(E7=0,"",1-(F7/E7))
A8: 2025-03-21 | B8: Analyst 1 | C8: 100 | G8: =IF(E8=0,"",1-(F8/E8))
A9: 2025-03-21 | B9: Analyst 2 | C9: 100 | G9: =IF(E9=0,"",1-(F9/E9))
A10: 2025-03-24 | B10: Analyst 1 | C10: 150 | G10: =IF(E10=0,"",1-(F10/E10))
A11: 2025-03-24 | B11: Analyst 2 | C11: 150 | G11: =IF(E11=0,"",1-(F11/E11))
A12: 2025-03-25 | B12: Analyst 1 | C12: 150 | G12: =IF(E12=0,"",1-(F12/E12))
A13: 2025-03-25 | B13: Analyst 2 | C13: 150 | G13: =IF(E13=0,"",1-(F13/E13))
... A19: 2025-03-28 | B19: Analyst 2 | C19: 150 | G19: =IF(E19=0,"",1-(F19/E19))

Sheet Audit_Protocol
A1: 2025 340B Audit Protocol
A3: Phase 1 - Data request & setup
B4: Pull all 2025 claims with the required 12 fields.
B5: Load store mapping, 340B ID, covered entity, and entity address master data.
B6: Confirm provider NPI format and source files are complete.
A9: Phase 2 - Claims testing
B10: Use row-level scrubbing to validate completeness, NPI, NDC, site, and entity fields.
B11: Assign PASS or REVIEW and a risk score for every claim.
B12: Escalate missing mappings and invalid provider / NDC issues.
A15: Phase 3 - 100% review analytics
B16: Use Dashboard to monitor total claims, pass rate, high-risk claims, and issue counts.
B17: Track daily analyst throughput and QA accuracy on Daily_Production.
B18: Perform 10% QA sample review each day.
A21: Phase 4 - Monthly self-audit outputs
B22: Save issue logs and QA results centrally.
B23: Summarize non-confirmed / high-risk claims for leadership.
B24: Update policy and procedure gaps identified during the review.
